Workbook

Sheet Draft Board
A1: BAWSE LEAGUE — CHAMPIONSHIP LEAGUE DRAFT BOARD
A2: Round | B2: Manager 1 | C2: Manager 2 | D2: Manager 3 | E2: Manager 4 | F2: Manager 5 | G2: Manager 6 | H2: Manager 7 | I2: Manager 8 | J2: Manager 9 | K2: Manager 10
A3: 1 →
A4: 2 ←
A5: 3 →
A6: 4 ←
A7: 5 →
A8: 6 ←
A9: 7 →
A10: 8 ←
A11: 9 →
A12: 10 ←
A13: 11 →
A14: Picks | B14: =COUNTA(B3:B13) | C14: =COUNTA(C3:C13) | D14: =COUNTA(D3:D13) | E14: =COUNTA(E3:E13) | F14: =COUNTA(F3:F13) | G14: =COUNTA(G3:G13) | H14: =COUNTA(H3:H13) | I14: =COUNTA(I3:I13) | ... K14: =COUNTA(K3:K13)
B15: Snake draft: odd rounds left→right, even rounds right←left. A pick that turns RED is a duplicate — re-pick immediately.
A17: LIVE DRAFT TRACKER
A18: League | B18: Teams | C18: Drafted | D18: Undrafted
A19: MLB | B19: 30 | C19: =COUNTIF('Draft Board'!$B$3:$K$13,"MLB: *") | D19: =B19-C19
A20: NBA | B20: 30 | C20: =COUNTIF('Draft Board'!$B$3:$K$13,"NBA: *") | D20: =B20-C20
A21: NHL | B21: 32 | C21: =COUNTIF('Draft Board'!$B$3:$K$13,"NHL: *") | D21: =B21-C21
A22: NFL | B22: 32 | C22: =COUNTIF('Draft Board'!$B$3:$K$13,"NFL: *") | D22: =B22-C22
A23: NCAAF | B23: 138 | C23: =COUNTIF('Draft Board'!$B$3:$K$13,"NCAAF: *") | D23: =B23-C23
A24: NCAAM | B24: 365 | C24: =COUNTIF('Draft Board'!$B$3:$K$13,"NCAAM: *") | D24: =B24-C24
A25: EPL | B25: 20 | C25: =COUNTIF('Draft Board'!$B$3:$K$13,"EPL: *") | D25: =B25-C25
A26: TOTAL | B26: =SUM(B19:B25) | C26: =SUM(C19:C25) | D26: =SUM(D19:D25)
A27: "Drafted" counts drafted teams; undrafted teams stay unowned for the season.

Sheet Master Team List
A1: League | B1: Team | C1: Draft Name (dropdown source) | D1: Drafted?
A2: MLB | B2: Arizona Diamondbacks | C2: MLB: Arizona Diamondbacks | D2: =IF(COUNTIF('Draft Board'!$B$3:$K$13,C2)>0,"DRAFTED","")
A3: MLB | B3: Athletics | C3: MLB: Athletics | D3: =IF(COUNTIF('Draft Board'!$B$3:$K$13,C3)>0,"DRAFTED","")
A4: MLB | B4: Atlanta Braves | C4: MLB: Atlanta Braves | D4: =IF(COUNTIF('Draft Board'!$B$3:$K$13,C4)>0,"DRAFTED","")
A5: MLB | B5: Baltimore Orioles | C5: MLB: Baltimore Orioles | D5: =IF(COUNTIF('Draft Board'!$B$3:$K$13,C5)>0,"DRAFTED","")
A6: MLB | B6: Boston Red Sox | C6: MLB: Boston Red Sox | D6: =IF(COUNTIF('Draft Board'!$B$3:$K$13,C6)>0,"DRAFTED","")
A7: MLB | B7: Chicago Cubs | C7: MLB: Chicago Cubs | D7: =IF(COUNTIF('Draft Board'!$B$3:$K$13,C7)>0,"DRAFTED","")
A8: MLB | B8: Chicago White Sox | C8: MLB: Chicago White Sox | D8: =IF(COUNTIF('Draft Board'!$B$3:$K$13,C8)>0,"DRAFTED","")
A9: MLB | B9: Cincinnati Reds | C9: MLB: Cincinnati Reds | D9: =IF(COUNTIF('Draft Board'!$B$3:$K$13,C9)>0,"DRAFTED","")
A10: MLB | B10: Cleveland Guardians | C10: MLB: Cleveland Guardians | D10: =IF(COUNTIF('Draft Board'!$B$3:$K$13,C10)>0,"DRAFTED","")
A11: MLB | B11: Colorado Rockies | C11: MLB: Colorado Rockies | D11: =IF(COUNTIF('Draft Board'!$B$3:$K$13,C11)>0,"DRAFTED","")
A12: MLB | B12: Detroit Tigers | C12: MLB: Detroit Tigers | D12: =IF(COUNTIF('Draft Board'!$B$3:$K$13,C12)>0,"DRAFTED","")
A13: MLB | B13: Houston Astros | C13: MLB: Houston Astros | D13: =IF(COUNTIF('Draft Board'!$B$3:$K$13,C13)>0,"DRAFTED","")
... A648: EPL | B648: Tottenham Hotspur | C648: EPL: Tottenham Hotspur | D648: =IF(COUNTIF('Draft Board'!$B$3:$K$13,C648)>0,"DRAFTED","")

Sheet Odds Cheatsheet
A1: CHAMPIONSHIP FUTURES CHEATSHEET
A2: Odds as of July 2026 (MLB All-Star break) — current for a late-July 2026 draft. Spot-check lines the week of draft night.
A4: MLB — 2026 World Series | E4: NBA — 2027 NBA Championship
A5: Book: BetMGM via VegasInsider | E5: Book: BetMGM via VegasInsider
A6: Team | B6: Odds | C6: Implied % | E6: Team | F6: Odds | G6: Implied %
A7: Los Angeles Dodgers | B7: 180 | C7: =100/(B7+100) | E7: Oklahoma City Thunder | F7: 260 | G7: =100/(F7+100)
A8: New York Yankees | B8: 550 | C8: =100/(B8+100) | E8: San Antonio Spurs | F8: 260 | G8: =100/(F8+100)
A9: Milwaukee Brewers | B9: 1000 | C9: =100/(B9+100) | E9: New York Knicks | F9: 900 | G9: =100/(F9+100)
A10: Atlanta Braves | B10: 1200 | C10: =100/(B10+100) | E10: Boston Celtics | F10: 1400 | G10: =100/(F10+100)
A11: Seattle Mariners | B11: 1200 | C11: =100/(B11+100) | E11: Philadelphia 76ers | F11: 1800 | G11: =100/(F11+100)
A12: Philadelphia Phillies | B12: 1200 | C12: =100/(B12+100) | E12: Cleveland Cavaliers | F12: 2000 | G12: =100/(F12+100)
A13: Tampa Bay Rays | B13: 1700 | C13: =100/(B13+100) | E13: Toronto Raptors | F13: 2200 | G13: =100/(F13+100)
A14: Chicago Cubs | B14: 2000 | C14: =100/(B14+100) | E14: Miami Heat | F14: 2500 | G14: =100/(F14+100)
A15: Texas Rangers | B15: 2500 | C15: =100/(B15+100) | E15: Denver Nuggets | F15: 2500 | G15: =100/(F15+100)
A16: Cleveland Guardians | B16: 3000 | C16: =100/(B16+100) | E16: Minnesota Timberwolves | F16: 2500 | G16: =100/(F16+100)
A17: Toronto Blue Jays | B17: 3500 | C17: =100/(B17+100) | E17: Detroit Pistons | F17: 2500 | G17: =100/(F17+100)
A18: Chicago White Sox | B18: 4000 | C18: =100/(B18+100) | E18: Golden State Warriors | F18: 3000 | G18: =100/(F18+100)
... A26: Minnesota Twins | B26: 12500 | C26: =100/(B26+100) | E26: Phoenix Suns | F26: 12500 | G26: =100/(F26+100)
A29: NHL — 2027 Stanley Cup | E29: NFL — Super Bowl LXI (2026 season)
A30: Book: DraftKings via CBS Sports | E30: Book: DraftKings via VegasInsider
A31: Team | B31: Odds | C31: Implied % | E31: Team | F31: Odds | G31: Implied %
A32: Carolina Hurricanes | B32: 700 | C32: =100/(B32+100) | E32: Los Angeles Rams | F32: 550 | G32: =100/(F32+100)
A33: Colorado Avalanche | B33: 800 | C33: =100/(B33+100) | E33: Baltimore Ravens | F33: 1000 | G33: =100/(F33+100)
A34: Vegas Golden Knights | B34: 850 | C34: =100/(B34+100) | E34: Buffalo Bills | F34: 1000 | G34: =100/(F34+100)
A35: Edmonton Oilers | B35: 1100 | C35: =100/(B35+100) | E35: Seattle Seahawks | F35: 1100 | G35: =100/(F35+100)
A36: Florida Panthers | B36: 1100 | C36: =100/(B36+100) | E36: New England Patriots | F36: 1600 | G36: =100/(F36+100)
A37: Tampa Bay Lightning | B37: 1200 | C37: =100/(B37+100) | E37: Kansas City Chiefs | F37: 1600 | G37: =100/(F37+100)
A38: Minnesota Wild | B38: 1400 | C38: =100/(B38+100) | E38: Philadelphia Eagles | F38: 1600 | G38: =100/(F38+100)
A39: Dallas Stars | B39: 1500 | C39: =100/(B39+100) | E39: Los Angeles Chargers | F39: 1700 | G39: =100/(F39+100)
A40: Ottawa Senators | B40: 1600 | C40: =100/(B40+100) | E40: Houston Texans | F40: 1800 | G40: =100/(F40+100)
A41: Montreal Canadiens | B41: 2200 | C41: =100/(B41+100) | E41: Green Bay Packers | F41: 1800 | G41: =100/(F41+100)
A42: Anaheim Ducks | B42: 2500 | C42: =100/(B42+100) | E42: San Francisco 49ers | F42: 1900 | G42: =100/(F42+100)
A43: Buffalo Sabres | B43: 2500 | C43: =100/(B43+100) | E43: Detroit Lions | F43: 1900 | G43: =100/(F43+100)
... A51: Pittsburgh Penguins | B51: 5500 | C51: =100/(B51+100) | E51: Pittsburgh Steelers | F51: 5000 | G51: =100/(F51+100)
A54: NCAAF — 2026-27 CFP National Championship | E54: NCAAM — 2027 NCAA Tournament Champion
A55: Book: VegasInsider consensus | E55: Book: Bovada
A56: Team | B56: Odds | C56: Implied % | E56: Team | F56: Odds | G56: Implied %
A57: Ohio State | B57: 600 | C57: =100/(B57+100) | E57: Florida | F57: 600 | G57: =100/(F57+100)
A58: Notre Dame | B58: 700 | C58: =100/(B58+100) | E58: Duke | F58: 700 | G58: =100/(F58+100)
A59: Texas | B59: 750 | C59: =100/(B59+100) | E59: Michigan | F59: 1200 | G59: =100/(F59+100)
...

Sheet How To Use
A1: HOW TO USE THIS DRAFT TOOL
A3: 1. Before the draft
A4: • Type your 10 manager names into the yellow cells on the Draft Board (row 2).
A5: • Randomize draft order; the column order IS the draft order.
A6: • The Odds Cheatsheet is current as of July 2026 — spot-check big movers the week of the draft.
A7: • Update the Master Team List for renames, relocation, EPL promotion/relegation, and FBS/D1 changes.
A9: 2. During the draft
A10: • On each pick, use the dropdown in your cell for that round. Odd rounds go left→right, even rounds right←left (snake).
A11: • Teams are listed as “LEAGUE: Team”. Type the league prefix to jump there in the dropdown.
A12: • A duplicate pick turns RED in both cells — the later pick is void and must be re-made.
A13: • The Live Draft Tracker (below the board) shows how many teams remain undrafted in each league.
A14: • The Master Team List marks every individually drafted team with “DRAFTED”.
... A22: Cells you should edit: yellow. Everything with formulas updates automatically.
